Workbook

Sheet Assumptions
A1: AI-ENABLED CLOUD & DEVOPS AGENCY MODEL
A2: Target: $1M ARR in 12 Months
A4: PRICING & TIERS
A5: Simple Tier - Monthly Price | B5: 500 | C5: Editable assumption
A6: Standard Tier - Monthly Price | B6: 1000 | C6: Editable assumption
A7: Complex Tier - Monthly Price | B7: 2000 | C7: Editable assumption
A8: Onboarding Fee (one-time) | B8: 2000 | C8: Editable assumption
A10: Client Distribution %
A11: Simple Tier % | B11: 0.6 | C11: Editable assumption
A12: Standard Tier % | B12: 0.25 | C12: Editable assumption
A13: Complex Tier % | B13: 0.15 | C13: Editable assumption
A14: Distribution Check | B14: =B11+B12+B13 -> 1
A16: UPSELL & EMERGENCY
A17: Emergency Incident Fee (avg) | B17: 200 | C17: $100-$150 range per SLA
A18: % Clients w/ Emergency/mo | B18: 0.15 | C18: Editable assumption
A19: Product Break-Fix Fee (avg) | B19: 175 | C19: Editable assumption
A20: % Clients w/ Product Issue/mo | B20: 0.1 | C20: Editable assumption
A22: Blended Upsell per Client/mo | B22: =B17*B18+B19*B20 -> 47.5 | C22: Auto-calculated
A24: COST ASSUMPTIONS
A25: Eng Hourly Cost | B25: 75 | C25: Editable assumption
A26: Cloud Cost per Client/mo | B26: 40 | C26: DB, servers, etc.
A27: AI Token Cost per Client/mo | B27: 8 | C27: Monitoring + debugging agent
A28: Team Burn (Fixed Monthly) | B28: 80000 | C28: Salaries, overhead, etc.
A29: S&M as % of Revenue | B29: 0.15 | C29: On top of team burn
A31: Human Hours per Client/mo
A32: Simple Tier | B32: 0.75 | C32: hrs/mo - AI handles ~90%
A33: Standard Tier | B33: 2 | C33: hrs/mo - AI handles ~75%
A34: Complex Tier | B34: 5 | C34: hrs/mo - AI handles ~60%
A35: Onboarding (one-time) | B35: 2.5 | C35: hrs - AI agent does heavy lifting
A36: Emergency Incident | B36: 3 | C36: hrs per incident avg
A37: Core Team Capacity (hrs/wk) | B37: 20 | C37: 2 engs, covered by $80K burn
A38: Core Team Capacity (hrs/mo) | B38: =B37*4.33 -> 86.6 | C38: Auto-calculated (~80 hrs/mo)
A39: New Hire Capacity (hrs/wk) | B39: 50 | C39: 100% client-facing
A41: GROWTH ASSUMPTIONS
A42: Monthly Churn Rate | B42: 0.03 | C42: Editable assumption
A43: Base New Clients (Month 1) | B43: 4 | C43: → Revenue Model!D2
A44: Monthly Growth Rate | B44: 0.15 | C44: → Revenue Model!F2
A45: Curve Steepness | B45: 1 | C45: → Revenue Model!H2 | <1 dampens, =1 pure, >1 amplifies
A46: Formula: Base × (1+Growth%)^(Steep×(M-1))
A47: Target ARR | B47: 1000000 | C47: $1M target
...

Sheet Revenue Model
A1: REVENUE MODEL - 12 MONTH BUILDUP
A2: Growth Curve Inputs: | C2: Base: | D2: 4 | E2: Growth%: | F2: 0.15 | G2: Steepness: | H2: 3 | I2: Churn: | J2: 0.03
A3: CLIENT ACQUISITION | C3: M1 | D3: M2 | E3: M3 | F3: M4 | G3: M5 | H3: M6 | I3: M7 | J3: M8 | K3: M9 | L3: M10 | M3: M11 | N3: M12 | O3: 12-Mo Total
A4: New Clients (Gross) | C4: =ROUND($D$2*(1+$F$2)^($H$2*0),0) -> 4 | D4: =ROUND($D$2*(1+$F$2)^($H$2*1),0) -> 6 | E4: =ROUND($D$2*(1+$F$2)^($H$2*2),0) -> 9 | F4: =ROUND($D$2*(1+$F$2)^($H$2*3),0) -> 14 | G4: =ROUND($D$2*(1+$F$2)^($H$2*4),0) -> 21 | H4: =ROUND($D$2*(1+$F$2)^($H$2*5),0) -> 33 | I4: =ROUND($D$2*(1+$F$2)^($H$2*6),0) -> 50 | J4: =ROUND($D$2*(1+$F$2)^($H$2*7),0) -> 75 | K4: =ROUND($D$2*(1+$F$2)^($H$2*8),0) -> 115 | L4: =ROUND($D$2*(1+$F$2)^($H$2*9),0) -> 174 | M4: =ROUND($D$2*(1+$F$2)^($H$2*10),0) -> 265 | N4: =ROUND($D$2*(1+$F$2)^($H$2*11),0) -> 403 | O4: =SUM(C4:N4) -> 1169
A5: Churned Clients | C5: 0 | D5: =ROUND(C8*$J$2,0) -> 0 | E5: =ROUND(D8*$J$2,0) -> 0 | F5: =ROUND(E8*$J$2,0) -> 1 | G5: =ROUND(F8*$J$2,0) -> 1 | H5: =ROUND(G8*$J$2,0) -> 2 | I5: =ROUND(H8*$J$2,0) -> 2 | J5: =ROUND(I8*$J$2,0) -> 4 | K5: =ROUND(J8*$J$2,0) -> 6 | ... N5: =ROUND(M8*$J$2,0) -> 22 | O5: =SUM(C5:N5) -> 61
A6: Net New Clients | C6: =C4-C5 -> 4 | D6: =D4-D5 -> 6 | E6: =E4-E5 -> 9 | F6: =F4-F5 -> 13 | G6: =G4-G5 -> 20 | H6: =H4-H5 -> 31 | I6: =I4-I5 -> 48 | J6: =J4-J5 -> 71 | ... N6: =N4-N5 -> 381 | O6: =SUM(C6:N6) -> 1108
A8: Total Clients (EoM) | C8: =C6 -> 4 | D8: =C8+D6 -> 10 | E8: =D8+E6 -> 19 | F8: =E8+F6 -> 32 | G8: =F8+G6 -> 52 | H8: =G8+H6 -> 83 | I8: =H8+I6 -> 131 | J8: =I8+J6 -> 202 | K8: =J8+K6 -> 311 | ... N8: =M8+N6 -> 1108
A9: Simple Clients | C9: =ROUND(C8*0.6,0) -> 2 | D9: =ROUND(D8*0.6,0) -> 6 | E9: =ROUND(E8*0.6,0) -> 11 | F9: =ROUND(F8*0.6,0) -> 19 | G9: =ROUND(G8*0.6,0) -> 31 | H9: =ROUND(H8*0.6,0) -> 50 | I9: =ROUND(I8*0.6,0) -> 79 | J9: =ROUND(J8*0.6,0) -> 121 | ... N9: =ROUND(N8*0.6,0) -> 665
A10: Standard Clients | C10: =ROUND(C8*0.25,0) -> 1 | D10: =ROUND(D8*0.25,0) -> 3 | E10: =ROUND(E8*0.25,0) -> 5 | F10: =ROUND(F8*0.25,0) -> 8 | G10: =ROUND(G8*0.25,0) -> 13 | H10: =ROUND(H8*0.25,0) -> 21 | I10: =ROUND(I8*0.25,0) -> 33 | J10: =ROUND(J8*0.25,0) -> 51 | ... N10: =ROUND(N8*0.25,0) -> 277
A11: Complex Clients | C11: =C8-C9-C10 -> 1 | D11: =D8-D9-D10 -> 1 | E11: =E8-E9-E10 -> 3 | F11: =F8-F9-F10 -> 5 | G11: =G8-G9-G10 -> 8 | H11: =H8-H9-H10 -> 12 | I11: =I8-I9-I10 -> 19 | J11: =J8-J9-J10 -> 30 | ... N11: =N8-N9-N10 -> 166
A13: MONTHLY RECURRING REVENUE | C13: M1 | D13: M2 | E13: M3 | F13: M4 | G13: M5 | H13: M6 | I13: M7 | J13: M8 | K13: M9 | L13: M10 | M13: M11 | N13: M12
A14: Simple Tier MRR | C14: =C9*500 -> 1000 | D14: =D9*500 -> 3000 | E14: =E9*500 -> 5500 | F14: =F9*500 -> 9500 | G14: =G9*500 -> 15500 | H14: =H9*500 -> 25000 | I14: =I9*500 -> 39500 | J14: =J9*500 -> 60500 | ... N14: =N9*500 -> 332500
A15: Standard Tier MRR | C15: =C10*1000 -> 1000 | D15: =D10*1000 -> 3000 | E15: =E10*1000 -> 5000 | F15: =F10*1000 -> 8000 | G15: =G10*1000 -> 13000 | H15: =H10*1000 -> 21000 | I15: =I10*1000 -> 33000 | J15: =J10*1000 -> 51000 | ... N15: =N10*1000 -> 277000
A16: Complex Tier MRR | C16: =C11*2000 -> 2000 | D16: =D11*2000 -> 2000 | E16: =E11*2000 -> 6000 | F16: =F11*2000 -> 10000 | G16: =G11*2000 -> 16000 | H16: =H11*2000 -> 24000 | I16: =I11*2000 -> 38000 | J16: =J11*2000 -> 60000 | ... N16: =N11*2000 -> 332000
A17: Total Subscription MRR | C17: =C14+C15+C16 -> 4000 | D17: =D14+D15+D16 -> 8000 | E17: =E14+E15+E16 -> 16500 | F17: =F14+F15+F16 -> 27500 | G17: =G14+G15+G16 -> 44500 | H17: =H14+H15+H16 -> 70000 | I17: =I14+I15+I16 -> 110500 | J17: =J14+J15+J16 -> 171500 | ... N17: =N14+N15+N16 -> 941500 | O17: =SUM(C17:N17) -> 2679500
A18: Onboarding Revenue | C18: =C4*2000 -> 8000 | D18: =D4*2000 -> 12000 | E18: =E4*2000 -> 18000 | F18: =F4*2000 -> 28000 | G18: =G4*2000 -> 42000 | H18: =H4*2000 -> 66000 | I18: =I4*2000 -> 100000 | J18: =J4*2000 -> 150000 | ... N18: =N4*2000 -> 806000 | O18: =SUM(C18:N18) -> 2338000
A19: Emergency Upsell | C19: =ROUND(C8*0.15,0)*125 -> 125 | D19: =ROUND(D8*0.15,0)*125 -> 250 | E19: =ROUND(E8*0.15,0)*125 -> 375 | F19: =ROUND(F8*0.15,0)*125 -> 625 | G19: =ROUND(G8*0.15,0)*125 -> 1000 | H19: =ROUND(H8*0.15,0)*125 -> 1500 | I19: =ROUND(I8*0.15,0)*125 -> 2500 | J19: =ROUND(J8*0.15,0)*125 -> 3750 | ... N19: =ROUND(N8*0.15,0)*125 -> 20750 | O19: =SUM(C19:N19) -> 59250
A20: Product Break-Fix Upsell | C20: =ROUND(C8*0.1,0)*175 -> 0 | D20: =ROUND(D8*0.1,0)*175 -> 175 | E20: =ROUND(E8*0.1,0)*175 -> 350 | F20: =ROUND(F8*0.1,0)*175 -> 525 | G20: =ROUND(G8*0.1,0)*175 -> 875 | H20: =ROUND(H8*0.1,0)*175 -> 1400 | I20: =ROUND(I8*0.1,0)*175 -> 2275 | J20: =ROUND(J8*0.1,0)*175 -> 3500 | ... N20: =ROUND(N8*0.1,0)*175 -> 19425 | O20: =SUM(C20:N20) -> 55125
A21: Total Monthly Revenue | C21: =C17+C18+C19+C20 -> 12125 | D21: =D17+D18+D19+D20 -> 20425 | E21: =E17+E18+E19+E20 -> 35225 | F21: =F17+F18+F19+F20 -> 56650 | G21: =G17+G18+G19+G20 -> 88375 | H21: =H17+H18+H19+H20 -> 138900 | I21: =I17+I18+I19+I20 -> 215275 | J21: =J17+J18+J19+J20 -> 328750 | ... N21: =N17+N18+N19+N20 -> 1787675 | O21: =SUM(C21:N21) -> 5131875
A23: Implied ARR (MRR x 12) | C23: =C17*12 -> 48000 | D23: =D17*12 -> 96000 | E23: =E17*12 -> 198000 | F23: =F17*12 -> 330000 | G23: =G17*12 -> 534000 | H23: =H17*12 -> 840000 | I23: =I17*12 -> 1326000 | J23: =J17*12 -> 2058000 | ... N23: =N17*12 -> 11298000
C25: M1 | D25: M2 | E25: M3 | F25: M4 | G25: M5 | H25: M6 | I25: M7 | J25: M8 | K25: M9 | L25: M10 | M25: M11 | N25: M12
A26: Total Clients | C26: =C8 -> 4 | D26: =D8 -> 10 | E26: =E8 -> 19 | F26: =F8 -> 32 | G26: =G8 -> 52 | H26: =H8 -> 83 | I26: =I8 -> 131 | J26: =J8 -> 202 | ... N26: =N8 -> 1108

Sheet Cost Structure
A1: COST STRUCTURE - 12 MONTH BUILDUP
A3: FIXED COSTS | C3: M1 | D3: M2 | E3: M3 | F3: M4 | G3: M5 | H3: M6 | I3: M7 | J3: M8 | K3: M9 | L3: M10 | M3: M11 | N3: M12
A4: Team Burn (Salaries + Overhead) | C4: 80000 | D4: 80000 | E4: 80000 | F4: 80000 | G4: 80000 | H4: 80000 | I4: 80000 | J4: 80000 | K4: 80000 | L4: 80000 | M4: 80000 | N4: 80000
A5: Total Fixed Costs | C5: =C4 -> 80000 | D5: =D4 -> 80000 | E5: =E4 -> 80000 | F5: =F4 -> 80000 | G5: =G4 -> 80000 | H5: =H4 -> 80000 | I5: =I4 -> 80000 | J5: =J4 -> 80000 | ... N5: =N4 -> 80000
A7: VARIABLE COSTS (per client) | C7: M1 | D7: M2 | E7: M3 | F7: M4 | G7: M5 | H7: M6 | I7: M7 | J7: M8 | K7: M9 | L7: M10 | M7: M11 | N7: M12
A8: Cloud Hosting ($40/client) | C8: ='Revenue Model'!C8*40 -> 160 | D8: ='Revenue Model'!D8*40 -> 400 | E8: ='Revenue Model'!E8*40 -> 760 | F8: ='Revenue Model'!F8*40 -> 1280 | G8: ='Revenue Model'!G8*40 -> 2080 | H8: ='Revenue Model'!H8*40 -> 3320 | I8: ='Revenue Model'!I8*40 -> 5240 | J8: ='Revenue Model'!J8*40 -> 8080 | ... N8: ='Revenue Model'!N8*40 -> 44320
A9: AI Token Costs ($8/client) | C9: ='Revenue Model'!C8*8 -> 32 | D9: ='Revenue Model'!D8*8 -> 80 | E9: ='Revenue Model'!E8*8 -> 152 | F9: ='Revenue Model'!F8*8 -> 256 | G9: ='Revenue Model'!G8*8 -> 416 | H9: ='Revenue Model'!H8*8 -> 664 | I9: ='Revenue Model'!I8*8 -> 1048 | J9: ='Revenue Model'!J8*8 -> 1616 | ... N9: ='Revenue Model'!N8*8 -> 8864
A10: Total Client Hours Needed | C10: ='Revenue Model'!C9*0.75+'Revenue Model'!C10*2+'Revenue Model'!C11*5+'Revenue Model'!C4*2.5+ROUND('Revenue Model'!C8*0.15,0)*3 -> 21.5 | D10: ='Revenue Model'!D9*0.75+'Revenue Model'!D10*2+'Revenue Model'!D11*5+'Revenue Model'!D4*2.5+ROUND('Revenue Model'!D8*0.15,0)*3 -> 36.5 | E10: ='Revenue Model'!E9*0.75+'Revenue Model'!E10*2+'Revenue Model'!E11*5+'Revenue Model'!E4*2.5+ROUND('Revenue Model'!E8*0.15,0)*3 -> 64.75 | F10: ='Revenue Model'!F9*0.75+'Revenue Model'!F10*2+'Revenue Model'!F11*5+'Revenue Model'!F4*2.5+ROUND('Revenue Model'!F8*0.15,0)*3 -> 105.25 | G10: ='Revenue Model'!G9*0.75+'Revenue Model'!G10*2+'Revenue Model'!G11*5+'Revenue Model'!G4*2.5+ROUND('Revenue Model'!G8*0.15,0)*3 -> 165.75 | H10: ='Revenue Model'!H9*0.75+'Revenue Model'!H10*2+'Revenue Model'!H11*5+'Revenue Model'!H4*2.5+ROUND('Revenue Model'!H8*0.15,0)*3 -> 258 | I10: ='Revenue Model'!I9*0.75+'Revenue Model'!I10*2+'Revenue Model'!I11*5+'Revenue Model'!I4*2.5+ROUND('Revenue Model'!I8*0.15,0)*3 -> 405.25 | J10: ='Revenue Model'!J9*0.75+'Revenue Model'!J10*2+'Revenue Model'!J11*5+'Revenue Model'!J4*2.5+ROUND('Revenue Model'!J8*0.15,0)*3 -> 620.25 | ... N10: ='Revenue Model'!N9*0.75+'Revenue Model'!N10*2+'Revenue Model'!N11*5+'Revenue Model'!N4*2.5+ROUND('Revenue Model'!N8*0.15,0)*3 -> 3388.25
A11: Core Team Absorbed (free) | C11: =MIN(C10,86.6) -> 21.5 | D11: =MIN(D10,86.6) -> 36.5 | E11: =MIN(E10,86.6) -> 64.75 | F11: =MIN(F10,86.6) -> 86.6 | G11: =MIN(G10,86.6) -> 86.6 | H11: =MIN(H10,86.6) -> 86.6 | I11: =MIN(I10,86.6) -> 86.6 | J11: =MIN(J10,86.6) -> 86.6 | ... N11: =MIN(N10,86.6) -> 86.6
A12: Overflow Hours | C12: =MAX(C10-86.6,0) -> 0 | D12: =MAX(D10-86.6,0) -> 0 | E12: =MAX(E10-86.6,0) -> 0 | F12: =MAX(F10-86.6,0) -> 18.65 | G12: =MAX(G10-86.6,0) -> 79.15 | H12: =MAX(H10-86.6,0) -> 171.4 | I12: =MAX(I10-86.6,0) -> 318.65 | J12: =MAX(J10-86.6,0) -> 533.65 | ... N12: =MAX(N10-86.6,0) -> 3301.65
A13: Overflow Eng Cost ($75/hr) | C13: =C12*75 -> 0 | D13: =D12*75 -> 0 | E13: =E12*75 -> 0 | F13: =F12*75 -> 1398.75 | G13: =G12*75 -> 5936.25 | H13: =H12*75 -> 12855 | I13: =I12*75 -> 23898.75 | J13: =J12*75 -> 40023.75 | ... N13: =N12*75 -> 247623.75
A14: Headcount: Additional Hires | C14: =IF(C12=0,0,CEILING(C12/216.5,1)) -> 0 | D14: =IF(D12=0,0,CEILING(D12/216.5,1)) -> 0 | E14: =IF(E12=0,0,CEILING(E12/216.5,1)) -> 0 | F14: =IF(F12=0,0,CEILING(F12/216.5,1)) -> 1 | G14: =IF(G12=0,0,CEILING(G12/216.5,1)) -> 1 | H14: =IF(H12=0,0,CEILING(H12/216.5,1)) -> 1 | I14: =IF(I12=0,0,CEILING(I12/216.5,1)) -> 2 | J14: =IF(J12=0,0,CEILING(J12/216.5,1)) -> 3 | ... N14: =IF(N12=0,0,CEILING(N12/216.5,1)) -> 16
A16: Total Variable Costs | C16: =C8+C9+C13 -> 192 | D16: =D8+D9+D13 -> 480 | E16: =E8+E9+E13 -> 912 | F16: =F8+F9+F13 -> 2934.75 | G16: =G8+G9+G13 -> 8432.25 | H16: =H8+H9+H13 -> 16839 | I16: =I8+I9+I13 -> 30186.75 | J16: =J8+J9+J13 -> 49719.75 | ... N16: =N8+N9+N13 -> 300807.75
A17: SALES & MARKETING | C17: M1 | D17: M2 | E17: M3 | F17: M4 | G17: M5 | H17: M6 | I17: M7 | J17: M8 | K17: M9 | L17: M10 | M17: M11 | N17: M12
A18: S&M Spend (15% of Revenue) | C18: ='Revenue Model'!C21*0.15 -> 1818.75 | D18: ='Revenue Model'!D21*0.15 -> 3063.75 | E18: ='Revenue Model'!E21*0.15 -> 5283.75 | F18: ='Revenue Model'!F21*0.15 -> 8497.5 | G18: ='Revenue Model'!G21*0.15 -> 13256.25 | H18: ='Revenue Model'!H21*0.15 -> 20835 | I18: ='Revenue Model'!I21*0.15 -> 32291.25 | J18: ='Revenue Model'!J21*0.15 -> 49312.5 | ... N18: ='Revenue Model'!N21*0.15 -> 268151.25
A20: TOTAL COSTS | C20: M1 | D20: M2 | E20: M3 | F20: M4 | G20: M5 | H20: M6 | I20: M7 | J20: M8 | K20: M9 | L20: M10 | M20: M11 | N20: M12
A21: Total Monthly Costs | C21: =C5+C16+C18 -> 82010.75 | D21: =D5+D16+D18 -> 83543.75 | E21: =E5+E16+E18 -> 86195.75 | F21: =F5+F16+F18 -> 91432.25 | G21: =G5+G16+G18 -> 101688.5 | H21: =H5+H16+H18 -> 117674 | I21: =I5+I16+I18 -> 142478 | J21: =J5+J16+J18 -> 179032.25 | ... N21: =N5+N16+N18 -> 648959
A22: Cumulative Costs | C22: =C21 -> 82010.75 | D22: =C22+D21 -> 165554.5 | E22: =D22+E21 -> 251750.25 | F22: =E22+F21 -> 343182.5 | G22: =F22+G21 -> 444871 | H22: =G22+H21 -> 562545 | I22: =H22+I21 -> 705023 | J22: =I22+J21 -> 884055.25 | K22: =J22+K21 -> 1119814.5 | ... N22: =M22+N21 -> 2541153.8

Sheet Unit Economics
A1: UNIT ECONOMICS BY TIER
A3: Per-Client Monthly Unit Economics | C3: Simple | D3: Standard | E3: Complex
A4: REVENUE
A5: Monthly Subscription | C5: 500 | D5: 1000 | E5: 2000
A6: Blended Upsell/mo | C6: =36.25 -> 36.25 | D6: =36.25 -> 36.25 | E6: =36.25 -> 36.25
A7: Total Monthly Revenue | C7: =C5+C6 -> 536.25 | D7: =D5+D6 -> 1036.25 | E7: =E5+E6 -> 2036.25
A9: VARIABLE COSTS
A10: Cloud Hosting | C10: 40 | D10: 40 | E10: 40
A11: AI Tokens | C11: 8 | D11: 8 | E11: 8
A12: Eng Hours (if overflow @ $75/hr) | C12: =0.75*75 -> 56.25 | D12: =2*75 -> 150 | E12: =5*75 -> 375
A13: Emergency Eng (share @ $75/hr) | C13: =0.15*3*75 -> 33.75 | D13: =0.15*3*75 -> 33.75 | E13: =0.15*3*75 -> 33.75
A14: Total Variable Cost (at scale) | C14: =C10+C11+C12+C13 -> 138 | D14: =D10+D11+D12+D13 -> 231.75 | E14: =E10+E11+E12+E13 -> 456.75
A15: Variable Cost (within core cap.) | C15: =C10+C11 -> 48 | D15: =D10+D11 -> 48 | E15: =E10+E11 -> 48
A16: CONTRIBUTION MARGIN (at scale) | C16: =C7-C14 -> 398.25 | D16: =D7-D14 -> 804.5 | E16: =E7-E14 -> 1579.5
A17: Contribution Margin % (at scale) | C17: =C16/C7 -> 0.74265734 | D17: =D16/D7 -> 0.77635706 | E17: =E16/E7 -> 0.77569061
A19: LIFETIME VALUE (LTV) | C19: Simple | D19: Standard | E19: Complex
A20: Avg Lifetime (months @ 3% churn) | C20: =1/0.03 -> 33.333333 | D20: =1/0.03 -> 33.333333 | E20: =1/0.03 -> 33.333333
A21: LTV (Revenue) | C21: =C7*C20 -> 17875 | D21: =D7*D20 -> 34541.667 | E21: =E7*E20 -> 67875
A22: LTV (Gross Profit) | C22: =C16*C20 -> 13275 | D22: =D16*D20 -> 26816.667 | E22: =E16*E20 -> 52650
A23: Onboarding Fee (one-time) | C23: 2000 | D23: 2000 | E23: 2000
A24: Total LTV incl. Onboarding | C24: =C22+C23 -> 15275 | D24: =D22+D23 -> 28816.667 | E24: =E22+E23 -> 54650

Sheet P&L Summary
A1: P&L SUMMARY - PATH TO $1M ARR
C3: M1 | D3: M2 | E3: M3 | F3: M4 | G3: M5 | H3: M6 | I3: M7 | J3: M8 | K3: M9 | L3: M10 | M3: M11 | N3: M12 | O3: 12-Mo Total
A4: Total Revenue | C4: ='Revenue Model'!C21 -> 12125 | D4: ='Revenue Model'!D21 -> 20425 | E4: ='Revenue Model'!E21 -> 35225 | F4: ='Revenue Model'!F21 -> 56650 | G4: ='Revenue Model'!G21 -> 88375 | H4: ='Revenue Model'!H21 -> 138900 | I4: ='Revenue Model'!I21 -> 215275 | J4: ='Revenue Model'!J21 -> 328750 | ... N4: ='Revenue Model'!N21 -> 1787675 | O4: =SUM(C4:N4) -> 5131875
A5: Subscription MRR | C5: ='Revenue Model'!C17 -> 4000 | D5: ='Revenue Model'!D17 -> 8000 | E5: ='Revenue Model'!E17 -> 16500 | F5: ='Revenue Model'!F17 -> 27500 | G5: ='Revenue Model'!G17 -> 44500 | H5: ='Revenue Model'!H17 -> 70000 | I5: ='Revenue Model'!I17 -> 110500 | J5: ='Revenue Model'!J17 -> 171500 | ... N5: ='Revenue Model'!N17 -> 941500 | O5: =SUM(C5:N5) -> 2679500
A6: Onboarding Revenue | C6: ='Revenue Model'!C18 -> 8000 | D6: ='Revenue Model'!D18 -> 12000 | E6: ='Revenue Model'!E18 -> 18000 | F6: ='Revenue Model'!F18 -> 28000 | G6: ='Revenue Model'!G18 -> 42000 | H6: ='Revenue Model'!H18 -> 66000 | I6: ='Revenue Model'!I18 -> 100000 | J6: ='Revenue Model'!J18 -> 150000 | ... N6: ='Revenue Model'!N18 -> 806000 | O6: =SUM(C6:N6) -> 2338000
A7: Emergency Upsell | C7: ='Revenue Model'!C19 -> 125 | D7: ='Revenue Model'!D19 -> 250 | E7: ='Revenue Model'!E19 -> 375 | F7: ='Revenue Model'!F19 -> 625 | G7: ='Revenue Model'!G19 -> 1000 | H7: ='Revenue Model'!H19 -> 1500 | I7: ='Revenue Model'!I19 -> 2500 | J7: ='Revenue Model'!J19 -> 3750 | ... N7: ='Revenue Model'!N19 -> 20750 | O7: =SUM(C7:N7) -> 59250
A8: Product Break-Fix | C8: ='Revenue Model'!C20 -> 0 | D8: ='Revenue Model'!D20 -> 175 | E8: ='Revenue Model'!E20 -> 350 | F8: ='Revenue Model'!F20 -> 525 | G8: ='Revenue Model'!G20 -> 875 | H8: ='Revenue Model'!H20 -> 1400 | I8: ='Revenue Model'!I20 -> 2275 | J8: ='Revenue Model'!J20 -> 3500 | ... N8: ='Revenue Model'!N20 -> 19425 | O8: =SUM(C8:N8) -> 55125
A10: Total Costs | C10: ='Cost Structure'!C21 -> 82010.75 | D10: ='Cost Structure'!D21 -> 83543.75 | E10: ='Cost Structure'!E21 -> 86195.75 | F10: ='Cost Structure'!F21 -> 91432.25 | G10: ='Cost Structure'!G21 -> 101688.5 | H10: ='Cost Structure'!H21 -> 117674 | I10: ='Cost Structure'!I21 -> 142478 | J10: ='Cost Structure'!J21 -> 179032.25 | ... N10: ='Cost Structure'!N21 -> 648959 | O10: =SUM(C10:N10) -> 2541153.8
A11: Fixed (Team Burn) | C11: ='Cost Structure'!C5 -> 80000 | D11: ='Cost Structure'!D5 -> 80000 | E11: ='Cost Structure'!E5 -> 80000 | F11: ='Cost Structure'!F5 -> 80000 | G11: ='Cost Structure'!G5 -> 80000 | H11: ='Cost Structure'!H5 -> 80000 | I11: ='Cost Structure'!I5 -> 80000 | J11: ='Cost Structure'!J5 -> 80000 | ... N11: ='Cost Structure'!N5 -> 80000 | O11: =SUM(C11:N11) -> 960000
A12: Variable Costs | C12: ='Cost Structure'!C16 -> 192 | D12: ='Cost Structure'!D16 -> 480 | E12: ='Cost Structure'!E16 -> 912 | F12: ='Cost Structure'!F16 -> 2934.75 | G12: ='Cost Structure'!G16 -> 8432.25 | H12: ='Cost Structure'!H16 -> 16839 | I12: ='Cost Structure'!I16 -> 30186.75 | J12: ='Cost Structure'!J16 -> 49719.75 | ... N12: ='Cost Structure'!N16 -> 300807.75 | O12: =SUM(C12:N12) -> 811372.5
A13: S&M | C13: ='Cost Structure'!C18 -> 1818.75 | D13: ='Cost Structure'!D18 -> 3063.75 | E13: ='Cost Structure'!E18 -> 5283.75 | F13: ='Cost Structure'!F18 -> 8497.5 | G13: ='Cost Structure'!G18 -> 13256.25 | H13: ='Cost Structure'!H18 -> 20835 | I13: ='Cost Structure'!I18 -> 32291.25 | J13: ='Cost Structure'!J18 -> 49312.5 | ... N13: ='Cost Structure'!N18 -> 268151.25 | O13: =SUM(C13:N13) -> 769781.25
A15: Net Income / (Loss) | C15: =C4-C10 -> -69885.75 | D15: =D4-D10 -> -63118.75 | E15: =E4-E10 -> -50970.75 | F15: =F4-F10 -> -34782.25 | G15: =G4-G10 -> -13313.5 | H15: =H4-H10 -> 21226 | I15: =I4-I10 -> 72797 | J15: =J4-J10 -> 149717.75 | ... N15: =N4-N10 -> 1138716 | O15: =SUM(C15:N15) -> 2590721.2
A16: Net Margin % | C16: =IF(C4=0,0,C15/C4) -> -5.7637732 | D16: =IF(D4=0,0,D15/D4) -> -3.0902693 | E16: =IF(E4=0,0,E15/E4) -> -1.447005 | F16: =IF(F4=0,0,F15/F4) -> -0.613985 | G16: =IF(G4=0,0,G15/G4) -> -0.15064781 | H16: =IF(H4=0,0,H15/H4) -> 0.15281497 | I16: =IF(I4=0,0,I15/I4) -> 0.33815817 | J16: =IF(J4=0,0,J15/J4) -> 0.45541521 | ... O16: =IF(O4=0,0,O15/O4) -> 0.50482938
A18: KEY METRICS | C18: M1 | D18: M2 | E18: M3 | F18: M4 | G18: M5 | H18: M6 | I18: M7 | J18: M8 | K18: M9 | L18: M10 | M18: M11 | N18: M12
A19: Cumulative Cash Flow | C19: =C15 -> -69885.75 | D19: =C19+D15 -> -133004.5 | E19: =D19+E15 -> -183975.25 | F19: =E19+F15 -> -218757.5 | G19: =F19+G15 -> -232071 | H19: =G19+H15 -> -210845 | I19: =H19+I15 -> -138048 | J19: =I19+J15 -> 11669.75 | K19: =J19+K15 -> 280710.5 | ... N19: =M19+N15 -> 2590721.2
A20: Total Clients | C20: ='Revenue Model'!C8 -> 4 | D20: ='Revenue Model'!D8 -> 10 | E20: ='Revenue Model'!E8 -> 19 | F20: ='Revenue Model'!F8 -> 32 | G20: ='Revenue Model'!G8 -> 52 | H20: ='Revenue Model'!H8 -> 83 | I20: ='Revenue Model'!I8 -> 131 | J20: ='Revenue Model'!J8 -> 202 | ... N20: ='Revenue Model'!N8 -> 1108
A21: Implied ARR (Sub MRR x 12) | C21: =C5*12 -> 48000 | D21: =D5*12 -> 96000 | E21: =E5*12 -> 198000 | F21: =F5*12 -> 330000 | G21: =G5*12 -> 534000 | H21: =H5*12 -> 840000 | I21: =I5*12 -> 1326000 | J21: =J5*12 -> 2058000 | ... N21: =N5*12 -> 11298000
A22: Total Revenue (Cumulative) | C22: =C4 -> 12125 | D22: =C22+D4 -> 32550 | E22: =D22+E4 -> 67775 | F22: =E22+F4 -> 124425 | G22: =F22+G4 -> 212800 | H22: =G22+H4 -> 351700 | I22: =H22+I4 -> 566975 | J22: =I22+J4 -> 895725 | K22: =J22+K4 -> 1400525 | ... N22: =M22+N4 -> 5131875
A23: Months to Profitability | C23: Month 12 — Profitable! (+$10.9K net income)
